Workbook

Sheet resumen_metricas_dinamico
A1: id_cuentas | B1: nombre_campaña | C1: fecha_inicio | D1: fecha_fin | E1: eje | F1: area | G1: estado | H1: {={"digital_impresiones";SUMIF(DIGITAL!A2:A1000,A2:A1000,DIGITAL!C2:C1000)}} -> digital_impresiones | I1: {={"digital_visualizaciones";SUMIF(DIGITAL!A2:A1000,A2:A1000,DIGITAL!D2:D1000)}} -> digital_visualizaciones | J1: {={"digital_clics";SUMIF(DIGITAL!A2:A1000,A2:A1000,DIGITAL!E2:E1000)}} -> digital_clics | K1: {={"meta_alcance";IFERROR(VLOOKUP(A2:A1000,ALCANCE!$A$2:$C1000,2,0),0)}} -> meta_alcance | L1: {={"meta_frecuencia";IFERROR(VLOOKUP(A2:A1000,ALCANCE!$A$2:$C1000,3,0),0)}} -> meta_frecuencia | M1: {={"frecuencia_total";IFERROR(H2:H1000/K2:K1000,0)}} -> frecuencia_total | N1: {={"mails_enviados";SUMIF(MAIL!A2:A1000,A2:A1000,MAIL!B2:B1000)}} -> mails_enviados | O1: {={"mails_entregados";SUMIF(MAIL!A2:A1000,A2:A1000,MAIL!C2:C1000)}} -> mails_entregados | P1: {={"mails_aperturas";SUMIF(MAIL!A2:A1000,A2:A1000,MAIL!D2:D1000)}} -> mails_aperturas | Q1: {={"mails_clics";SUMIF(MAIL!A2:A1000,A2:A1000,MAIL!E2:E1000)}} -> mails_clics | R1: {={"call_enviado";SUMIF(CC!A2:A1000,A2:A1000,CC!B2:B1000)}} -> call_enviado | S1: {={"call_discado";SUMIF(CC!A2:A1000,A2:A1000,CC!C2:C1000)}} -> call_discado | T1: {={"call_contactados";SUMIF(CC!A2:A1000,A2:A1000,CC!D2:D1000)}} -> call_contactados | U1: {={"call_efectivos";SUMIF(CC!A2:A1000,A2:A1000,CC!E2:E1000)}} -> call_efectivos | V1: {={"ivr_audiencia";SUMIF(IVR!A2:A1000,A2:A1000,IVR!B2:B1000)}} -> ivr_audiencia | W1: {={"ivr_realizados";SUMIF(IVR!A2:A1000,A2:A1000,IVR!C2:C1000)}} -> ivr_realizados | X1: {={"ivr_atendidos";SUMIF(IVR!A2:A1000,A2:A1000,IVR!D2:D1000)}} -> ivr_atendidos | Y1: {={"ivr_escucha75";SUMIF(IVR!A2:A1000,A2:A1000,IVR!E2:E1000)}} -> ivr_escucha75 | Z1: {={"ivr_marque1";SUMIF(IVR!A2:A1000,A2:A1000,IVR!F2:F1000)}} -> ivr_marque1 | AA1: {={"sms_enviados";SUMIF(SMS!A2:A1000,A2:A1000,SMS!B2:B1000)}} -> sms_enviados | AB1: {={"sms_entregados";SUMIF(SMS!A2:A1000,A2:A1000,SMS!C2:C1000)}} -> sms_entregados | AC1: {={"sms_clics";SUMIF(SMS!A2:A1000,A2:A1000,SMS!D2:D1000)}} -> sms_clics | AD1: {={"pieza_meta";IFERROR(VLOOKUP(A2:A1000,URLs!D1:F1000,3,0),"")}} -> pieza_meta | AE1: {={"pieza_mail";IFERROR(VLOOKUP(A2:A1000,URLs!A1:C1000,3,0),"")}} -> pieza_mail
A2: =IFERROR(__xludf.DUMMYFUNCTION("QUERY(Cuentas!A2:G1000,""SELECT * WHERE Col1 is not null AND Col7 <> 'Pendiente'"",0)"),"1871-AGOEDUGC") -> 1871-AGOEDUGC | B2: =IFERROR(__xludf.DUMMYFUNCTION("""COMPUTED_VALUE"""),"Campaña GCBA | Educación | TUMO") -> Campaña GCBA | Educación | TUMO | C2: =IFERROR(__xludf.DUMMYFUNCTION("""COMPUTED_VALUE"""),45959.0) -> 45959 | D2: =IFERROR(__xludf.DUMMYFUNCTION("""COMPUTED_VALUE"""),46203.0) -> 46203 | E2: =IFERROR(__xludf.DUMMYFUNCTION("""COMPUTED_VALUE"""),"Cuidado") -> Cuidado | F2: =IFERROR(__xludf.DUMMYFUNCTION("""COMPUTED_VALUE"""),"Educación") -> Educación | G2: =IFERROR(__xludf.DUMMYFUNCTION("""COMPUTED_VALUE"""),"Finalizada") -> Finalizada | H2: 201273767 | I2: 21618564 | J2: 2637230 | K2: 9405671 | L2: 1.211467 | M2: 21.399193 | N2: 858783 | O2: 844304 | P2: 285060 | Q2: 8156 | R2: 4476 | S2: 4476 | T2: 1117 | U2: 854 | V2: 0 | W2: 0 | X2: 0 | Y2: 0 | Z2: 0 | AA2: 0 | AB2: 0 | AC2: 0 | AD2: https://www.facebook.com/reel/818777800864033
A3: =IFERROR(__xludf.DUMMYFUNCTION("""COMPUTED_VALUE"""),"1895-SEPEPHGC") -> 1895-SEPEPHGC | B3: =IFERROR(__xludf.DUMMYFUNCTION("""COMPUTED_VALUE"""),"PIEZAS M2 | MEPHU | REPAVIMENTACIÓN") -> PIEZAS M2 | MEPHU | REPAVIMENTACIÓN | C3: =IFERROR(__xludf.DUMMYFUNCTION("""COMPUTED_VALUE"""),46052.0) -> 46052 | D3: =IFERROR(__xludf.DUMMYFUNCTION("""COMPUTED_VALUE"""),46178.0) -> 46178 | E3: =IFERROR(__xludf.DUMMYFUNCTION("""COMPUTED_VALUE"""),"M2") -> M2 | F3: =IFERROR(__xludf.DUMMYFUNCTION("""COMPUTED_VALUE"""),"Espacio Público e Higiene Urbana") -> Espacio Público e Higiene Urbana | G3: =IFERROR(__xludf.DUMMYFUNCTION("""COMPUTED_VALUE"""),"Finalizada") -> Finalizada | H3: 0 | I3: 0 | J3: 0 | K3: 0 | L3: 0 | M3: 0 | N3: 21556 | O3: 21228 | P3: 7666 | Q3: 393 | R3: 0 | S3: 0 | T3: 0 | U3: 0 | V3: 0 | W3: 0 | X3: 0 | Y3: 0 | Z3: 0 | AA3: 0 | AB3: 0 | AC3: 0 | AE3: Pieza
A4: =IFERROR(__xludf.DUMMYFUNCTION("""COMPUTED_VALUE"""),"1896-SEPEPHGC") -> 1896-SEPEPHGC | B4: =IFERROR(__xludf.DUMMYFUNCTION("""COMPUTED_VALUE"""),"PIEZAS M2 | MEPHU | LIMPIEZA INTENSIVA") -> PIEZAS M2 | MEPHU | LIMPIEZA INTENSIVA | C4: =IFERROR(__xludf.DUMMYFUNCTION("""COMPUTED_VALUE"""),46031.0) -> 46031 | D4: =IFERROR(__xludf.DUMMYFUNCTION("""COMPUTED_VALUE"""),46136.0) -> 46136 | E4: =IFERROR(__xludf.DUMMYFUNCTION("""COMPUTED_VALUE"""),"M2") -> M2 | F4: =IFERROR(__xludf.DUMMYFUNCTION("""COMPUTED_VALUE"""),"Espacio Público e Higiene Urbana") -> Espacio Público e Higiene Urbana | G4: =IFERROR(__xludf.DUMMYFUNCTION("""COMPUTED_VALUE"""),"Finalizada") -> Finalizada | H4: 0 | I4: 0 | J4: 0 | K4: 0 | L4: 0 | M4: 0 | N4: 648150 | O4: 634433 | P4: 181275 | Q4: 1540 | R4: 0 | S4: 0 | T4: 0 | U4: 0 | V4: 0 | W4: 0 | X4: 0 | Y4: 0 | Z4: 0 | AA4: 0 | AB4: 0 | AC4: 0 | AE4: Pieza
A5: =IFERROR(__xludf.DUMMYFUNCTION("""COMPUTED_VALUE"""),"1933-SEPINFGC") -> 1933-SEPINFGC | B5: =IFERROR(__xludf.DUMMYFUNCTION("""COMPUTED_VALUE"""),"CAMPAÑA GCBA | INFRAESTRUCTURA | Campaña 360° Movilidad 2025") -> CAMPAÑA GCBA | INFRAESTRUCTURA | Campaña 360° Movilidad 2025 | C5: =IFERROR(__xludf.DUMMYFUNCTION("""COMPUTED_VALUE"""),45936.0) -> 45936 | D5: =IFERROR(__xludf.DUMMYFUNCTION("""COMPUTED_VALUE"""),46081.0) -> 46081 | E5: =IFERROR(__xludf.DUMMYFUNCTION("""COMPUTED_VALUE"""),"Movilidad") -> Movilidad | F5: =IFERROR(__xludf.DUMMYFUNCTION("""COMPUTED_VALUE"""),"Infraestructura") -> Infraestructura | G5: =IFERROR(__xludf.DUMMYFUNCTION("""COMPUTED_VALUE"""),"Finalizada") -> Finalizada | H5: 120265231 | I5: 14353067 | J5: 530499 | K5: 6681997 | L5: 0.9273355 | M5: 17.998396 | N5: 2962736 | O5: 3124082 | P5: 1008617 | Q5: 19835 | R5: 0 | S5: 0 | T5: 0 | U5: 0 | V5: 0 | W5: 0 | X5: 0 | Y5: 0 | Z5: 0 | AA5: 16505 | AB5: 15794 | AC5: 82 | AD5: https://www.facebook.com/GCBA/posts/pfbid02ySETv8mbLPx3NFrrHh1eRhVRmMimid99iTcJQu2RtwUS7KCAiwKP9qoSStF1cMSml | AE5: Pieza
A6: =IFERROR(__xludf.DUMMYFUNCTION("""COMPUTED_VALUE"""),"1942-SEPEPHGC") -> 1942-SEPEPHGC | B6: =IFERROR(__xludf.DUMMYFUNCTION("""COMPUTED_VALUE"""),"DGPLES | MEPHU | REPARACIÓN DE VEREDAS") -> DGPLES | MEPHU | REPARACIÓN DE VEREDAS | C6: =IFERROR(__xludf.DUMMYFUNCTION("""COMPUTED_VALUE"""),46031.0) -> 46031 | D6: =IFERROR(__xludf.DUMMYFUNCTION("""COMPUTED_VALUE"""),46223.0) -> 46223 | E6: =IFERROR(__xludf.DUMMYFUNCTION("""COMPUTED_VALUE"""),"M2") -> M2 | F6: =IFERROR(__xludf.DUMMYFUNCTION("""COMPUTED_VALUE"""),"Espacio Público e Higiene Urbana") -> Espacio Público e Higiene Urbana | G6: =IFERROR(__xludf.DUMMYFUNCTION("""COMPUTED_VALUE"""),"Finalizada") -> Finalizada | H6: 0 | I6: 0 | J6: 0 | K6: 0 | L6: 0 | M6: 0 | N6: 69878 | O6: 68815 | P6: 23523 | Q6: 1379 | R6: 0 | S6: 0 | T6: 0 | U6: 0 | V6: 0 | W6: 0 | X6: 0 | Y6: 0 | Z6: 0 | AA6: 0 | AB6: 0 | AC6: 0 | AE6: Pieza
A7: =IFERROR(__xludf.DUMMYFUNCTION("""COMPUTED_VALUE"""),"1943-SEPEPHGC") -> 1943-SEPEPHGC | B7: =IFERROR(__xludf.DUMMYFUNCTION("""COMPUTED_VALUE"""),"DGPLES | MEPHU | READOQUINADO") -> DGPLES | MEPHU | READOQUINADO | C7: =IFERROR(__xludf.DUMMYFUNCTION("""COMPUTED_VALUE"""),46031.0) -> 46031 | D7: =IFERROR(__xludf.DUMMYFUNCTION("""COMPUTED_VALUE"""),46223.0) -> 46223 | E7: =IFERROR(__xludf.DUMMYFUNCTION("""COMPUTED_VALUE"""),"M2") -> M2 | F7: =IFERROR(__xludf.DUMMYFUNCTION("""COMPUTED_VALUE"""),"Espacio Público e Higiene Urbana") -> Espacio Público e Higiene Urbana | G7: =IFERROR(__xludf.DUMMYFUNCTION("""COMPUTED_VALUE"""),"Finalizada") -> Finalizada | H7: 0 | I7: 0 | J7: 0 | K7: 0 | L7: 0 | M7: 0 | N7: 15590 | O7: 15371 | P7: 5329 | Q7: 415 | R7: 0 | S7: 0 | T7: 0 | U7: 0 | V7: 0 | W7: 0 | X7: 0 | Y7: 0 | Z7: 0 | AA7: 0 | AB7: 0 | AC7: 0 | AE7: Pieza
A8: =IFERROR(__xludf.DUMMYFUNCTION("""COMPUTED_VALUE"""),"1946-SEPEPHGC") -> 1946-SEPEPHGC | B8: =IFERROR(__xludf.DUMMYFUNCTION("""COMPUTED_VALUE"""),"CAMPAÑA GCBA | MEPHU | PLUVIALES") -> CAMPAÑA GCBA | MEPHU | PLUVIALES | C8: =IFERROR(__xludf.DUMMYFUNCTION("""COMPUTED_VALUE"""),46038.0) -> 46038 | D8: =IFERROR(__xludf.DUMMYFUNCTION("""COMPUTED_VALUE"""),46223.0) -> 46223 | E8: =IFERROR(__xludf.DUMMYFUNCTION("""COMPUTED_VALUE"""),"M2") -> M2 | F8: =IFERROR(__xludf.DUMMYFUNCTION("""COMPUTED_VALUE"""),"Espacio Público e Higiene Urbana") -> Espacio Público e Higiene Urbana | G8: =IFERROR(__xludf.DUMMYFUNCTION("""COMPUTED_VALUE"""),"Finalizada") -> Finalizada | H8: 0 | I8: 0 | J8: 0 | K8: 0 | L8: 0 | M8: 0 | N8: 18528 | O8: 18309 | P8: 6404 | Q8: 426 | R8: 0 | S8: 0 | T8: 0 | U8: 0 | V8: 0 | W8: 0 | X8: 0 | Y8: 0 | Z8: 0 | AA8: 0 | AB8: 0 | AC8: 0 | AE8: Pieza
A9: =IFERROR(__xludf.DUMMYFUNCTION("""COMPUTED_VALUE"""),"1964-SEPEPHGC") -> 1964-SEPEPHGC | B9: =IFERROR(__xludf.DUMMYFUNCTION("""COMPUTED_VALUE"""),"MEPHU RECAMBIO TECNOLÓGICO M2") -> MEPHU RECAMBIO TECNOLÓGICO M2 | C9: =IFERROR(__xludf.DUMMYFUNCTION("""COMPUTED_VALUE"""),46071.0) -> 46071 | D9: =IFERROR(__xludf.DUMMYFUNCTION("""COMPUTED_VALUE"""),46220.0) -> 46220 | E9: =IFERROR(__xludf.DUMMYFUNCTION("""COMPUTED_VALUE"""),"M2") -> M2 | F9: =IFERROR(__xludf.DUMMYFUNCTION("""COMPUTED_VALUE"""),"Espacio Público e Higiene Urbana") -> Espacio Público e Higiene Urbana | G9: =IFERROR(__xludf.DUMMYFUNCTION("""COMPUTED_VALUE"""),"Finalizada") -> Finalizada | H9: 0 | I9: 0 | J9: 0 | K9: 0 | L9: 0 | M9: 0 | N9: 444872 | O9: 439325 | P9: 133653 | Q9: 3043 | R9: 0 | S9: 0 | T9: 0 | U9: 0 | V9: 0 | W9: 0 | X9: 0 | Y9: 0 | Z9: 0 | AA9: 0 | AB9: 0 | AC9: 0 | AE9: Pieza
A10: =IFERROR(__xludf.DUMMYFUNCTION("""COMPUTED_VALUE"""),"2033-SEPEPHGC") -> 2033-SEPEPHGC | B10: =IFERROR(__xludf.DUMMYFUNCTION("""COMPUTED_VALUE"""),"M2 PODA") -> M2 PODA | C10: =IFERROR(__xludf.DUMMYFUNCTION("""COMPUTED_VALUE"""),46035.0) -> 46035 | D10: =IFERROR(__xludf.DUMMYFUNCTION("""COMPUTED_VALUE"""),46216.0) -> 46216 | E10: =IFERROR(__xludf.DUMMYFUNCTION("""COMPUTED_VALUE"""),"M2") -> M2 | F10: =IFERROR(__xludf.DUMMYFUNCTION("""COMPUTED_VALUE"""),"Espacio Público e Higiene Urbana") -> Espacio Público e Higiene Urbana | G10: =IFERROR(__xludf.DUMMYFUNCTION("""COMPUTED_VALUE"""),"Finalizada") -> Finalizada | H10: 0 | I10: 0 | J10: 0 | K10: 0 | L10: 0 | M10: 0 | N10: 145204 | O10: 141927 | P10: 46936 | Q10: 2044 | R10: 0 | S10: 0 | T10: 0 | U10: 0 | V10: 0 | W10: 0 | X10: 0 | Y10: 0 | Z10: 0 | AA10: 0 | AB10: 0 | AC10: 0 | AE10: Pieza
A11: =IFERROR(__xludf.DUMMYFUNCTION("""COMPUTED_VALUE"""),"2100-OCTSALGC") -> 2100-OCTSALGC | B11: =IFERROR(__xludf.DUMMYFUNCTION("""COMPUTED_VALUE"""),"Cesac 12 - Más consultorios") -> Cesac 12 - Más consultorios | C11: =IFERROR(__xludf.DUMMYFUNCTION("""COMPUTED_VALUE"""),46013.0) -> 46013 | D11: =IFERROR(__xludf.DUMMYFUNCTION("""COMPUTED_VALUE"""),46027.0) -> 46027 | E11: =IFERROR(__xludf.DUMMYFUNCTION("""COMPUTED_VALUE"""),"Cuidado") -> Cuidado | F11: =IFERROR(__xludf.DUMMYFUNCTION("""COMPUTED_VALUE"""),"Salud") -> Salud | G11: =IFERROR(__xludf.DUMMYFUNCTION("""COMPUTED_VALUE"""),"Finalizada") -> Finalizada | H11: 5541119 | I11: 634751 | J11: 14536 | K11: 0 | L11: 0 | M11: 0 | N11: 81077 | O11: 79591 | P11: 31217 | Q11: 1060 | R11: 0 | S11: 0 | T11: 0 | U11: 0 | V11: 0 | W11: 0 | X11: 0 | Y11: 0 | Z11: 0 | AA11: 0 | AB11: 0 | AC11: 0
A12: =IFERROR(__xludf.DUMMYFUNCTION("""COMPUTED_VALUE"""),"2108-OCTEDUGC") -> 2108-OCTEDUGC | B12: =IFERROR(__xludf.DUMMYFUNCTION("""COMPUTED_VALUE"""),"Inscripción 2025 a Profesorados de la Ciudad") -> Inscripción 2025 a Profesorados de la Ciudad | C12: =IFERROR(__xludf.DUMMYFUNCTION("""COMPUTED_VALUE"""),45952.0) -> 45952 | D12: =IFERROR(__xludf.DUMMYFUNCTION("""COMPUTED_VALUE"""),46073.0) -> 46073 | E12: =IFERROR(__xludf.DUMMYFUNCTION("""COMPUTED_VALUE"""),"Cuidado") -> Cuidado | F12: =IFERROR(__xludf.DUMMYFUNCTION("""COMPUTED_VALUE"""),"Educación") -> Educación | G12: =IFERROR(__xludf.DUMMYFUNCTION("""COMPUTED_VALUE"""),"Finalizada") -> Finalizada | H12: 24528982 | I12: 0 | J12: 555619 | K12: 1745904 | L12: 1.3171446 | M12: 14.049445 | N12: 132413 | O12: 130535 | P12: 87400 | Q12: 8263 | R12: 0 | S12: 0 | T12: 0 | U12: 0 | V12: 0 | W12: 0 | X12: 0 | Y12: 0 | Z12: 0 | AA12: 0 | AB12: 0 | AC12: 0 | AD12: https://www.facebook.com/GCBA/posts/1295953569230956
A13: =IFERROR(__xludf.DUMMYFUNCTION("""COMPUTED_VALUE"""),"2109-OCTEPHGC") -> 2109-OCTEPHGC | B13: =IFERROR(__xludf.DUMMYFUNCTION("""COMPUTED_VALUE"""),"LIMPIEZA DE FACHADAS | M2") -> LIMPIEZA DE FACHADAS | M2 | C13: =IFERROR(__xludf.DUMMYFUNCTION("""COMPUTED_VALUE"""),46028.0) -> 46028 | D13: =IFERROR(__xludf.DUMMYFUNCTION("""COMPUTED_VALUE"""),46099.0) -> 46099 | E13: =IFERROR(__xludf.DUMMYFUNCTION("""COMPUTED_VALUE"""),"M2") -> M2 | F13: =IFERROR(__xludf.DUMMYFUNCTION("""COMPUTED_VALUE"""),"Espacio Público e Higiene Urbana") -> Espacio Público e Higiene Urbana | G13: =IFERROR(__xludf.DUMMYFUNCTION("""COMPUTED_VALUE"""),"Finalizada") -> Finalizada | H13: 0 | I13: 0 | J13: 0 | K13: 0 | L13: 0 | M13: 0 | N13: 923 | O13: 898 | P13: 294 | Q13: 38 | R13: 0 | S13: 0 | T13: 0 | U13: 0 | V13: 0 | W13: 0 | X13: 0 | Y13: 0 | Z13: 0 | AA13: 0 | AB13: 0 | AC13: 0 | AE13: Pieza
A14: =IFERROR(__xludf.DUMMYFUNCTION("""COMPUTED_VALUE"""),"2130-OCTSALGC") -> 2130-OCTSALGC | B14: =IFERROR(__xludf.DUMMYFUNCTION("""COMPUTED_VALUE"""),"Hospital Pirovano: Remodelaciones") -> Hospital Pirovano: Remodelaciones | C14: =IFERROR(__xludf.DUMMYFUNCTION("""COMPUTED_VALUE"""),46050.0) -> 46050 | D14: =IFERROR(__xludf.DUMMYFUNCTION("""COMPUTED_VALUE"""),46066.0) -> 46066 | E14: =IFERROR(__xludf.DUMMYFUNCTION("""COMPUTED_VALUE"""),"Cuidado") -> Cuidado | F14: =IFERROR(__xludf.DUMMYFUNCTION("""COMPUTED_VALUE"""),"Salud") -> Salud | G14: =IFERROR(__xludf.DUMMYFUNCTION("""COMPUTED_VALUE"""),"Finalizada") -> Finalizada | H14: 3945078 | I14: 0 | J14: 9197 | K14: 1208470 | L14: 1.0665105 | M14: 3.2645229 | N14: 100614 | O14: 99157 | P14: 42370 | Q14: 787 | R14: 0 | S14: 0 | T14: 0 | U14: 0 | V14: 0 | W14: 0 | X14: 0 | Y14: 0 | Z14: 0 | AA14: 0 | AB14: 0 | AC14: 0 | AE14: Pieza
A15: =IFERROR(__xludf.DUMMYFUNCTION("""COMPUTED_VALUE"""),"2145-OCTVINGC") -> 2145-OCTVINGC | B15: =IFERROR(__xludf.DUMMYFUNCTION("""COMPUTED_VALUE"""),"PIEZAS M2 | VINCULO CIUDADANO (GESTIÓN COMUNAL) | OBRAS EN PARQUES Y PLAZAS (PATIOS DE JUEGOS) Plan 2025") -> PIEZAS M2 | VINCULO CIUDADANO (GESTIÓN COMUNAL) | OBRAS EN PARQUES Y PLAZAS (PATIOS DE JUEGOS) Plan 2025 | C15: =IFERROR(__xludf.DUMMYFUNCTION("""COMPUTED_VALUE"""),46020.0) -> 46020 | D15: =IFERROR(__xludf.DUMMYFUNCTION("""COMPUTED_VALUE"""),46174.0) -> 46174 | E15: =IFERROR(__xludf.DUMMYFUNCTION("""COMPUTED_VALUE"""),"M2") -> M2 | F15: =IFERROR(__xludf.DUMMYFUNCTION("""COMPUTED_VALUE"""),"Vínculo Ciudadano") -> Vínculo Ciudadano | G15: =IFERROR(__xludf.DUMMYFUNCTION("""COMPUTED_VALUE"""),"Finalizada") -> Finalizada | H15: 2352745 | I15: 0 | J15: 7138 | K15: 1084144 | L15: 1.9502769 | M15: 2.1701407 | N15: 1136573 | O15: 1111059 | P15: 368628 | Q15: 9109 | R15: 0 | S15: 0 | T15: 0 | U15: 0 | V15: 0 | W15: 0 | X15: 0 | Y15: 0 | Z15: 0 | AA15: 0 | AB15: 0 | AC15: 0 | AD15: https://www.facebook.com/GCBA/posts/pfbid02j9NjjKC7QJSSUrKxkX55nDiWFRmCpVKSS3w7J3VpQA3DakuvLQQ5B3z96orCNRMUl | AE15: Pieza
A16: =IFERROR(__xludf.DUMMYFUNCTION("""COMPUTED_VALUE"""),"2183-OCTSALGC") -> 2183-OCTSALGC | B16: =IFERROR(__xludf.DUMMYFUNCTION("""COMPUTED_VALUE"""),"Sistema de Salud Público - Genérico") -> Sistema de Salud Público - Genérico | C16: =IFERROR(__xludf.DUMMYFUNCTION("""COMPUTED_VALUE"""),45992.0) -> 45992 | D16: =IFERROR(__xludf.DUMMYFUNCTION("""COMPUTED_VALUE"""),46068.0) -> 46068 | E16: =IFERROR(__xludf.DUMMYFUNCTION("""COMPUTED_VALUE"""),"Cuidado") -> Cuidado | F16: =IFERROR(__xludf.DUMMYFUNCTION("""COMPUTED_VALUE"""),"Salud") -> Salud | G16: =IFERROR(__xludf.DUMMYFUNCTION("""COMPUTED_VALUE"""),"Finalizada") -> Finalizada | H16: 63685126 | I16: 11819633 | J16: 218716 | K16: 2510514 | L16: 2.9775759 | M16: 25.367365 | N16: 0 | O16: 0 | P16: 0 | Q16: 0 | R16: 0 | S16: 0 | T16: 0 | U16: 0 | V16: 0 | W16: 0 | X16: 0 | Y16: 0 | Z16: 0 | AA16: 44842 | AB16: 43029 | AC16: 724 | AD16: https://www.facebook.com/GCBA/posts/pfbid02QwxLwyKnw9PCTX9BXhgSSH5hJ3u56noy7igZq9orxmSsVPqjj4MMUZ5SD9xXWWQ3l
A17: =IFERROR(__xludf.DUMMYFUNCTION("""COMPUTED_VALUE"""),"2227-NOVINFGC") -> 2227-NOVINFGC | B17: =IFERROR(__xludf.DUMMYFUNCTION("""COMPUTED_VALUE"""),"Infraestructura - SBASE | Campaña GCBA | Seguridad en Subte") -> Infraestructura - SBASE | Campaña GCBA | Seguridad en Subte | C17: =IFERROR(__xludf.DUMMYFUNCTION("""COMPUTED_VALUE"""),45981.0) -> 45981 | D17: =IFERROR(__xludf.DUMMYFUNCTION("""COMPUTED_VALUE"""),46037.0) -> 46037 | E17: =IFERROR(__xludf.DUMMYFUNCTION("""COMPUTED_VALUE"""),"Movilidad") -> Movilidad | F17: =IFERROR(__xludf.DUMMYFUNCTION("""COMPUTED_VALUE"""),"Infraestructura") -> Infraestructura | G17: =IFERROR(__xludf.DUMMYFUNCTION("""COMPUTED_VALUE"""),"Finalizada") -> Finalizada | H17: 56510666 | I17: 13306488 | J17: 109062 | K17: 2996348 | L17: 1.9993095 | M17: 18.859847 | N17: 448806 | O17: 441370 | P17: 157871 | Q17: 1073 | R17: 0 | S17: 0 | T17: 0 | U17: 0 | V17: 0 | W17: 0 | X17: 0 | Y17: 0 | Z17: 0 | AA17: 0 | AB17: 0 | AC17: 0 | AD17: https://www.facebook.com/GCBA/posts/pfbid0swuyoC42Lys1AAsD6UQ7EPU5B43KXVdVXxxXU4X9oHEJ7DjKXtavLAdDHd6BpccBl | AE17: Pieza
A18: =IFERROR(__xludf.DUMMYFUNCTION("""COMPUTED_VALUE"""),"2239-NOVSALGC") -> 2239-NOVSALGC | B18: =IFERROR(__xludf.DUMMYFUNCTION("""COMPUTED_VALUE"""),"Cuidados del Calor 2025 - Prevención") -> Cuidados del Calor 2025 - Prevención | C18: =IFERROR(__xludf.DUMMYFUNCTION("""COMPUTED_VALUE"""),45996.0) -> 45996 | D18: =IFERROR(__xludf.DUMMYFUNCTION("""COMPUTED_VALUE"""),46081.0) -> 46081 | E18: =IFERROR(__xludf.DUMMYFUNCTION("""COMPUTED_VALUE"""),"Cuidado") -> Cuidado | F18: =IFERROR(__xludf.DUMMYFUNCTION("""COMPUTED_VALUE"""),"Salud") -> Salud | G18: =IFERROR(__xludf.DUMMYFUNCTION("""COMPUTED_VALUE"""),"Finalizada") -> Finalizada | H18: 44318251 | I18: 7628858 | J18: 207888 | K18: 3270088 | L18: 3.1020116 | M18: 13.552617 | N18: 393084 | O18: 386497 | P18: 128673 | Q18: 1026 | R18: 0 | S18: 0 | T18: 0 | U18: 0 | V18: 60114 | W18: 60114 | X18: 50294 | Y18: 14803 | Z18: 0 | AA18: 44261 | AB18: 42094 | AC18: 432 | AD18: https://www.facebook.com/GCBA/posts/pfbid02fZ6eoJSg8zqDVE3RogP3nnn5hqo9sxTPxRzzs7HgyWNUmM6XZmtSLLNohgBDJZ2xl | AE18: Pieza
A19: =IFERROR(__xludf.DUMMYFUNCTION("""COMPUTED_VALUE"""),"2240-NOVSALGC") -> 2240-NOVSALGC | B19: =IFERROR(__xludf.DUMMYFUNCTION("""COMPUTED_VALUE"""),"Cuidados del Calor 2025 - Síntomas") -> Cuidados del Calor 2025 - Síntomas | C19: =IFERROR(__xludf.DUMMYFUNCTION("""COMPUTED_VALUE"""),46009.0) -> 46009 | D19: =IFERROR(__xludf.DUMMYFUNCTION("""COMPUTED_VALUE"""),46081.0) -> 46081 | E19: =IFERROR(__xludf.DUMMYFUNCTION("""COMPUTED_VALUE"""),"Cuidado") -> Cuidado | F19: =IFERROR(__xludf.DUMMYFUNCTION("""COMPUTED_VALUE"""),"Salud") -> Salud | G19: =IFERROR(__xludf.DUMMYFUNCTION("""COMPUTED_VALUE"""),"Finalizada") -> Finalizada | H19: 37792450 | I19: 5153493 | J19: 136800 | K19: 1979868 | L19: 3.4276906 | M19: 19.088369 | N19: 202759 | O19: 198265 | P19: 46872 | Q19: 167 | R19: 0 | S19: 0 | T19: 0 | U19: 0 | V19: 0 | W19: 0 | X19: 0 | Y19: 0 | Z19: 0 | AA19: 0 | AB19: 0 | AC19: 0 | AD19: https://www.facebook.com/GCBA/posts/pfbid02XEqLAZ3ja1iUkCQ1AFBkuUXwxFv9zsX5K86BwUhreM4wjGsmh9yx8x8cEFwBnwo1l | AE19: Pieza
A20: =IFERROR(__xludf.DUMMYFUNCTION("""COMPUTED_VALUE"""),"2241-NOVSALGC") -> 2241-NOVSALGC | B20: =IFERROR(__xludf.DUMMYFUNCTION("""COMPUTED_VALUE"""),"Cuidados del Calor 2025 - Alertas Meteorológicas") -> Cuidados del Calor 2025 - Alertas Meteorológicas | C20: =IFERROR(__xludf.DUMMYFUNCTION("""COMPUTED_VALUE"""),46020.0) -> 46020 | D20: =IFERROR(__xludf.DUMMYFUNCTION("""COMPUTED_VALUE"""),46058.0) -> 46058 | E20: =IFERROR(__xludf.DUMMYFUNCTION("""COMPUTED_VALUE"""),"Cuidado") -> Cuidado | F20: =IFERROR(__xludf.DUMMYFUNCTION("""COMPUTED_VALUE"""),"Salud") -> Salud | G20: =IFERROR(__xludf.DUMMYFUNCTION("""COMPUTED_VALUE"""),"Finalizada") -> Finalizada | H20: 6328947 | I20: 0 | J20: 50769 | K20: 2394484 | L20: 1.3164298 | M20: 2.6431361 | N20: 246623 | O20: 243978 | P20: 116854 | Q20: 114 | R20: 0 | S20: 0 | T20: 0 | U20: 0 | V20: 0 | W20: 0 | X20: 0 | Y20: 0 | Z20: 0 | AA20: 62485 | AB20: 59237 | AC20: 372 | AD20: https://www.facebook.com/GCBA/posts/pfbid02j9NjjKC7QJSSUrKxkX55nDiWFRmCpVKSS3w7J3VpQA3DakuvLQQ5B3z96orCNRMUl
A21: =IFERROR(__xludf.DUMMYFUNCTION("""COMPUTED_VALUE"""),"2255-NOVSALGC") -> 2255-NOVSALGC | B21: =IFERROR(__xludf.DUMMYFUNCTION("""COMPUTED_VALUE"""),"Sistema de Salud Público - Geolocalizado") -> Sistema de Salud Público - Geolocalizado | C21: =IFERROR(__xludf.DUMMYFUNCTION("""COMPUTED_VALUE"""),46008.0) -> 46008 | D21: =IFERROR(__xludf.DUMMYFUNCTION("""COMPUTED_VALUE"""),46068.0) -> 46068 | E21: =IFERROR(__xludf.DUMMYFUNCTION("""COMPUTED_VALUE"""),"Cuidado") -> Cuidado | F21: =IFERROR(__xludf.DUMMYFUNCTION("""COMPUTED_VALUE"""),"Salud") -> Salud | G21: =IFERROR(__xludf.DUMMYFUNCTION("""COMPUTED_VALUE"""),"Finalizada") -> Finalizada | H21: 38197009 | I21: 0 | J21: 552532 | K21: 1566896 | L21: 3.6226406 | M21: 24.377501 | N21: 907590 | O21: 862876 | P21: 284653 | Q21: 624 | R21: 0 | S21: 0 | T21: 0 | U21: 0 | V21: 0 | W21: 0 | X21: 0 | Y21: 0 | Z21: 0 | AA21: 0 | AB21: 0 | AC21: 0 | AD21: https://www.facebook.com/GCBA/posts/pfbid02dx5PKW9dhfnoR52qjj3Cxnq9opfoRmH6HwTJx9uacynmmZet5vn1FL6Xavv3J8ZXl | AE21: Pieza
A22: =IFERROR(__xludf.DUMMYFUNCTION("""COMPUTED_VALUE"""),"2256-NOVSALGC") -> 2256-NOVSALGC | B22: =IFERROR(__xludf.DUMMYFUNCTION("""COMPUTED_VALUE"""),"Sistema de Salud Público - Diferenciado x Audiencias") -> Sistema de Salud Público - Diferenciado x Audiencias | C22: =IFERROR(__xludf.DUMMYFUNCTION("""COMPUTED_VALUE"""),46010.0) -> 46010 | D22: =IFERROR(__xludf.DUMMYFUNCTION("""COMPUTED_VALUE"""),46068.0) -> 46068 | E22: =IFERROR(__xludf.DUMMYFUNCTION("""COMPUTED_VALUE"""),"Cuidado") -> Cuidado | F22: =IFERROR(__xludf.DUMMYFUNCTION("""COMPUTED_VALUE"""),"Salud") -> Salud | G22: =IFERROR(__xludf.DUMMYFUNCTION("""COMPUTED_VALUE"""),"Finalizada") -> Finalizada | H22: 28261480 | I22: 5404995 | J22: 94248 | K22: 1318610 | L22: 2.6421224 | M22: 21.432781 | N22: 348034 | O22: 344435 | P22: 178103 | Q22: 356 | R22: 0 | S22: 0 | T22: 0 | U22: 0 | V22: 0 | W22: 0 | X22: 0 | Y22: 0 | Z22: 0 | AA22: 0 | AB22: 0 | AC22: 0 | AD22: https://www.facebook.com/GCBA/posts/pfbid02SB5PG237gJvSQGMPLHpQAP5b6uxqxh8AqRUS3csVWmCnYyvd77i8d67LSBMnBtg8l | AE22: Pieza
A23: =IFERROR(__xludf.DUMMYFUNCTION("""COMPUTED_VALUE"""),"2293-NOVFESGC") -> 2293-NOVFESGC | B23: =IFERROR(__xludf.DUMMYFUNCTION("""COMPUTED_VALUE"""),"LA CIUDAD MAS LINDA DEL MUNDO") -> LA CIUDAD MAS LINDA DEL MUNDO | C23: =IFERROR(__xludf.DUMMYFUNCTION("""COMPUTED_VALUE"""),45994.0) -> 45994 | D23: =IFERROR(__xludf.DUMMYFUNCTION("""COMPUTED_VALUE"""),46053.0) -> 46053 | E23: =IFERROR(__xludf.DUMMYFUNCTION("""COMPUTED_VALUE"""),"Ciudad Atractiva") -> Ciudad Atractiva | F23: =IFERROR(__xludf.DUMMYFUNCTION("""COMPUTED_VALUE"""),"Festivales y Eventos") -> Festivales y Eventos | G23: =IFERROR(__xludf.DUMMYFUNCTION("""COMPUTED_VALUE"""),"Finalizada") -> Finalizada | H23: 75245249 | I23: 13466546 | J23: 799082 | K23: 7843297 | L23: 1.9541976 | M23: 9.5935739 | N23: 657996 | O23: 645327 | P23: 198939 | Q23: 10076 | R23: 0 | S23: 0 | T23: 0 | U23: 0 | V23: 0 | W23: 0 | X23: 0 | Y23: 0 | Z23: 0 | AA23: 0 | AB23: 0 | AC23: 0 | AD23: https://www.facebook.com/GCBA/posts/pfbid0yZFqpziwsSvEpGHnbKnvgTkMNo6Ys8gfLmUBqRKhRCH71tiHcf1cXzt2RhCmokjMl
A24: =IFERROR(__xludf.DUMMYFUNCTION("""COMPUTED_VALUE"""),"2318-ENEINFGC") -> 2318-ENEINFGC | B24: =IFERROR(__xludf.DUMMYFUNCTION("""COMPUTED_VALUE"""),"Infraestructura I Cambio de sentido Avelino Díaz y Las Casas") -> Infraestructura I Cambio de sentido Avelino Díaz y Las Casas | C24: =IFERROR(__xludf.DUMMYFUNCTION("""COMPUTED_VALUE"""),46040.0) -> 46040 | D24: =IFERROR(__xludf.DUMMYFUNCTION("""COMPUTED_VALUE"""),46053.0) -> 46053 | E24: =IFERROR(__xludf.DUMMYFUNCTION("""COMPUTED_VALUE"""),"M2") -> M2 | F24: =IFERROR(__xludf.DUMMYFUNCTION("""COMPUTED_VALUE"""),"Infraestructura") -> Infraestructura | G24: =IFERROR(__xludf.DUMMYFUNCTION("""COMPUTED_VALUE"""),"Finalizada") -> Finalizada | H24: 656152 | I24: 0 | J24: 4677 | K24: 293307 | L24: 2.2370826 | M24: 2.2370826 | N24: 34125 | O24: 33543 | P24: 11623 | Q24: 221 | R24: 0 | S24: 0 | T24: 0 | U24: 0 | V24: 0 | W24: 0 | X24: 0 | Y24: 0 | Z24: 0 | AA24: 0 | AB24: 0 | AC24: 0 | AD24: https://www.facebook.com/GCBA/posts/pfbid02fhrsXdCgnCn19Gs1k1PTjbTdAfYLBMqW3w4zhQLgJqH8r8uW4azYikpQk6Js8WNcl | AE24: Pieza
A25: =IFERROR(__xludf.DUMMYFUNCTION("""COMPUTED_VALUE"""),"2322-NOVEDUGC") -> 2322-NOVEDUGC | B25: =IFERROR(__xludf.DUMMYFUNCTION("""COMPUTED_VALUE"""),"TUMO Parque de la Innovación") -> TUMO Parque de la Innovación | C25: =IFERROR(__xludf.DUMMYFUNCTION("""COMPUTED_VALUE"""),46006.0) -> 46006 | D25: =IFERROR(__xludf.DUMMYFUNCTION("""COMPUTED_VALUE"""),46265.0) -> 46265 | E25: =IFERROR(__xludf.DUMMYFUNCTION("""COMPUTED_VALUE"""),"Cuidado") -> Cuidado | F25: =IFERROR(__xludf.DUMMYFUNCTION("""COMPUTED_VALUE"""),"Educación") -> Educación | G25: =IFERROR(__xludf.DUMMYFUNCTION("""COMPUTED_VALUE"""),"Activa") -> Activa | H25: 37630874 | I25: 2298580 | J25: 197893 | K25: 845956 | L25: 2.7451924 | M25: 44.483252 | N25: 390326 | O25: 382880 | P25: 132608 | Q25: 2847 | R25: 2471 | S25: 2471 | T25: 938 | U25: 695 | V25: 0 | W25: 0 | X25: 0 | Y25: 0 | Z25: 0 | AA25: 0 | AB25: 0 | AC25: 0 | AD25: https://www.facebook.com/reel/1259490412867632 | AE25: Pieza
A26: =IFERROR(__xludf.DUMMYFUNCTION("""COMPUTED_VALUE"""),"2407-DICDHHGC") -> 2407-DICDHHGC | B26: =IFERROR(__xludf.DUMMYFUNCTION("""COMPUTED_VALUE"""),"Red de atención - Comuna 14") -> Red de atención - Comuna 14 | C26: =IFERROR(__xludf.DUMMYFUNCTION("""COMPUTED_VALUE"""),46009.0) -> 46009 | D26: =IFERROR(__xludf.DUMMYFUNCTION("""COMPUTED_VALUE"""),46035.0) -> 46035 | E26: =IFERROR(__xludf.DUMMYFUNCTION("""COMPUTED_VALUE"""),"Cuidado") -> Cuidado | F26: =IFERROR(__xludf.DUMMYFUNCTION("""COMPUTED_VALUE"""),"Desarrollo Humano y Hábitat") -> Desarrollo Humano y Hábitat | G26: =IFERROR(__xludf.DUMMYFUNCTION("""COMPUTED_VALUE"""),"Finalizada") -> Finalizada | H26: 5648733 | I26: 908168 | J26: 31911 | K26: 345688 | L26: 1.5532706 | M26: 16.340553 | N26: 82291 | O26: 80644 | P26: 34390 | Q26: 427 | R26: 41000 | S26: 38657 | T26: 7137 | U26: 4305 | V26: 0 | W26: 0 | X26: 0 | Y26: 0 | Z26: 0 | AA26: 0 | AB26: 0 | AC26: 0 | AD26: https://www.facebook.com/GCBA/posts/pfbid034rFdFhu5CMuLHbUxCF393aMxjQ6Uzsq6seyeRjcjNKtzSymPzkApKt81BUxEeVj3l | AE26: Pieza
A27: =IFERROR(__xludf.DUMMYFUNCTION("""COMPUTED_VALUE"""),"2410-DICJDGAG") -> 2410-DICJDGAG | B27: =IFERROR(__xludf.DUMMYFUNCTION("""COMPUTED_VALUE"""),"RDV JM | Villa Devoto 15/12") -> RDV JM | Villa Devoto 15/12 | C27: =IFERROR(__xludf.DUMMYFUNCTION("""COMPUTED_VALUE"""),46013.0) -> 46013 | D27: =IFERROR(__xludf.DUMMYFUNCTION("""COMPUTED_VALUE"""),46024.0) -> 46024 | E27: =IFERROR(__xludf.DUMMYFUNCTION("""COMPUTED_VALUE"""),"Cercanía") -> Cercanía | F27: =IFERROR(__xludf.DUMMYFUNCTION("""COMPUTED_VALUE"""),"Jefatura de Gobierno") -> Jefatura de Gobierno | G27: =IFERROR(__xludf.DUMMYFUNCTION("""COMPUTED_VALUE"""),"Finalizada") -> Finalizada | H27: 14229634 | I27: 322142 | J27: 29184 | K27: 0 | L27: 0 | M27: 0 | N27: 30540 | O27: 30402 | P27: 9314 | Q27: 336 | R27: 0 | S27: 0 | T27: 0 | U27: 0 | V27: 20067.047 | W27: 20067.047 | X27: 18323.305 | Y27: 7084.077 | Z27: 180 | AA27: 0 | AB27: 0 | AC27: 0
A28: =IFERROR(__xludf.DUMMYFUNCTION("""COMPUTED_VALUE"""),"2412-DICJDGAG") -> 2412-DICJDGAG | B28: =IFERROR(__xludf.DUMMYFUNCTION("""COMPUTED_VALUE"""),"RDV JM | Colegiales 19/12") -> RDV JM | Colegiales 19/12 | C28: =IFERROR(__xludf.DUMMYFUNCTION("""COMPUTED_VALUE"""),46014.0) -> 46014 | D28: =IFERROR(__xludf.DUMMYFUNCTION("""COMPUTED_VALUE"""),46025.0) -> 46025 | E28: =IFERROR(__xludf.DUMMYFUNCTION("""COMPUTED_VALUE"""),"Cercanía") -> Cercanía | F28: =IFERROR(__xludf.DUMMYFUNCTION("""COMPUTED_VALUE"""),"Jefatura de Gobierno") -> Jefatura de Gobierno | G28: =IFERROR(__xludf.DUMMYFUNCTION("""COMPUTED_VALUE"""),"Finalizada") -> Finalizada | H28: 1782381 | I28: 139137 | J28: 7011 | K28: 0 | L28: 0 | M28: 0 | N28: 24878 | O28: 24515 | P28: 6879 | Q28: 163 | R28: 6770 | S28: 6769 | T28: 1751 | U28: 1295 | V28: 26545.519 | W28: 26545.519 | X28: 23902.879 | Y28: 10339.329 | Z28: 126 | AA28: 0 | AB28: 0 | AC28: 0
A29: =IFERROR(__xludf.DUMMYFUNCTION("""COMPUTED_VALUE"""),"2423-DICJDGGC") -> 2423-DICJDGGC | B29: =IFERROR(__xludf.DUMMYFUNCTION("""COMPUTED_VALUE"""),"Festejos Responsables 2025") -> Festejos Responsables 2025 | C29: =IFERROR(__xludf.DUMMYFUNCTION("""COMPUTED_VALUE"""),46014.0) -> 46014 | D29: =IFERROR(__xludf.DUMMYFUNCTION("""COMPUTED_VALUE"""),46023.0) -> 46023 | E29: =IFERROR(__xludf.DUMMYFUNCTION("""COMPUTED_VALUE"""),"Cuidado") -> Cuidado | F29: =IFERROR(__xludf.DUMMYFUNCTION("""COMPUTED_VALUE"""),"Jefatura de Gobierno") -> Jefatura de Gobierno | G29: =IFERROR(__xludf.DUMMYFUNCTION("""COMPUTED_VALUE"""),"Finalizada") -> Finalizada | H29: 113032 | I29: 0 | J29: 5003 | K29: 0 | L29: 0 | M29: 0 | N29: 497431 | O29: 490986 | P29: 208233 | Q29: 1469 | R29: 12000 | S29: 11037 | T29: 2752 | U29: 2052 | V29: 0 | W29: 0 | X29: 0 | Y29: 0 | Z29: 0 | AA29: 0 | AB29: 0 | AC29: 0
A30: =IFERROR(__xludf.DUMMYFUNCTION("""COMPUTED_VALUE"""),"2424-DICFESGC") -> 2424-DICFESGC | B30: =IFERROR(__xludf.DUMMYFUNCTION("""COMPUTED_VALUE"""),"Verano en Buenos Aires 2026 | Generico") -> Verano en Buenos Aires 2026 | Generico | C30: =IFERROR(__xludf.DUMMYFUNCTION("""COMPUTED_VALUE"""),46029.0) -> 46029 | D30: =IFERROR(__xludf.DUMMYFUNCTION("""COMPUTED_VALUE"""),46081.0) -> 46081 | E30: =IFERROR(__xludf.DUMMYFUNCTION("""COMPUTED_VALUE"""),"Ciudad Atractiva") -> Ciudad Atractiva | F30: =IFERROR(__xludf.DUMMYFUNCTION("""COMPUTED_VALUE"""),"Festivales y Eventos") -> Festivales y Eventos | G30: =IFERROR(__xludf.DUMMYFUNCTION("""COMPUTED_VALUE"""),"Finalizada") -> Finalizada | H30: 32919907 | I30: 2721109 | J30: 164357 | K30: 3975434 | L30: 2.6766625 | M30: 8.2808335 | N30: 306526 | O30: 303199 | P30: 151566 | Q30: 7233 | R30: 0 | S30: 0 | T30: 0 | U30: 0 | V30: 0 | W30: 0 | X30: 0 | Y30: 0 | Z30: 0 | AA30: 0 | AB30: 0 | AC30: 0 | AD30: https://www.facebook.com/GCBA/posts/pfbid02PmAtvdzD176mjzPpPRZmFQTNXzNjqoKr7o9wByEVUtzkzYpigMPqtXRGysNDa6Wjl | AE30: Pieza
A31: =IFERROR(__xludf.DUMMYFUNCTION("""COMPUTED_VALUE"""),"2425-DICEPHGC") -> 2425-DICEPHGC | B31: =IFERROR(__xludf.DUMMYFUNCTION("""COMPUTED_VALUE"""),"Parques Iluminados M2") -> Parques Iluminados M2 | C31: =IFERROR(__xludf.DUMMYFUNCTION("""COMPUTED_VALUE"""),46163.0) -> 46163 | D31: =IFERROR(__xludf.DUMMYFUNCTION("""COMPUTED_VALUE"""),46190.0) -> 46190 | E31: =IFERROR(__xludf.DUMMYFUNCTION("""COMPUTED_VALUE"""),"M2") -> M2 | F31: =IFERROR(__xludf.DUMMYFUNCTION("""COMPUTED_VALUE"""),"Espacio Público e Higiene Urbana") -> Espacio Público e Higiene Urbana | G31: =IFERROR(__xludf.DUMMYFUNCTION("""COMPUTED_VALUE"""),"Finalizada") -> Finalizada | H31: 0 | I31: 0 | J31: 0 | K31: 0 | L31: 0 | M31: 0 | N31: 21456 | O31: 21233 | P31: 7139 | Q31: 191 | R31: 0 | S31: 0 | T31: 0 | U31: 0 | V31: 0 | W31: 0 | X31: 0 | Y31: 0 | Z31: 0 | AA31: 0 | AB31: 0 | AC31: 0 | AE31: Pieza
A32: =IFERROR(__xludf.DUMMYFUNCTION("""COMPUTED_VALUE"""),"2426-DICSALGC") -> 2426-DICSALGC | B32: =IFERROR(__xludf.DUMMYFUNCTION("""COMPUTED_VALUE"""),"Deploy HIS Ambulatorio") -> Deploy HIS Ambulatorio | C32: =IFERROR(__xludf.DUMMYFUNCTION("""COMPUTED_VALUE"""),46030.0) -> 46030 | D32: =IFERROR(__xludf.DUMMYFUNCTION("""COMPUTED_VALUE"""),46030.0) -> 46030 | E32: =IFERROR(__xludf.DUMMYFUNCTION("""COMPUTED_VALUE"""),"Cuidado") -> Cuidado | F32: =IFERROR(__xludf.DUMMYFUNCTION("""COMPUTED_VALUE"""),"Salud") -> Salud | G32: =IFERROR(__xludf.DUMMYFUNCTION("""COMPUTED_VALUE"""),"Finalizada") -> Finalizada | H32: 0 | I32: 0 | J32: 0 | K32: 0 | L32: 0 | M32: 0 | N32: 3471 | O32: 3443 | P32: 1477 | Q32: 169 | R32: 0 | S32: 0 | T32: 0 | U32: 0 | V32: 0 | W32: 0 | X32: 0 | Y32: 0 | Z32: 0 | AA32: 0 | AB32: 0 | AC32: 0 | AE32: Pieza
A33: =IFERROR(__xludf.DUMMYFUNCTION("""COMPUTED_VALUE"""),"2430-DICPCCVC") -> 2430-DICPCCVC | B33: =IFERROR(__xludf.DUMMYFUNCTION("""COMPUTED_VALUE"""),"DGPCyC | Verano 2026 - Misión Bomberos: Un día en la estación") -> DGPCyC | Verano 2026 - Misión Bomberos: Un día en la estación | C33: =IFERROR(__xludf.DUMMYFUNCTION("""COMPUTED_VALUE"""),46029.0) -> 46029 | D33: =IFERROR(__xludf.DUMMYFUNCTION("""COMPUTED_VALUE"""),46029.0) -> 46029 | E33: =IFERROR(__xludf.DUMMYFUNCTION("""COMPUTED_VALUE"""),"Cercanía") -> Cercanía | F33: =IFERROR(__xludf.DUMMYFUNCTION("""COMPUTED_VALUE"""),"Cercanía y PC") -> Cercanía y PC | G33: =IFERROR(__xludf.DUMMYFUNCTION("""COMPUTED_VALUE"""),"Finalizada") -> Finalizada | H33: 0 | I33: 0 | J33: 0 | K33: 0 | L33: 0 | M33: 0 | N33: 26990 | O33: 26313 | P33: 4518 | Q33: 419 | R33: 0 | S33: 0 | T33: 0 | U33: 0 | V33: 0 | W33: 0 | X33: 0 | Y33: 0 | Z33: 0 | AA33: 0 | AB33: 0 | AC33: 0 | AE33: Pieza
A34: =IFERROR(__xludf.DUMMYFUNCTION("""COMPUTED_VALUE"""),"2433-DICFESGC") -> 2433-DICFESGC | B34: =IFERROR(__xludf.DUMMYFUNCTION("""COMPUTED_VALUE"""),"Verano en la Ciudad | AftersBA") -> Verano en la Ciudad | AftersBA | C34: =IFERROR(__xludf.DUMMYFUNCTION("""COMPUTED_VALUE"""),46035.0) -> 46035 | D34: =IFERROR(__xludf.DUMMYFUNCTION("""COMPUTED_VALUE"""),46071.0) -> 46071 | E34: =IFERROR(__xludf.DUMMYFUNCTION("""COMPUTED_VALUE"""),"Ciudad Atractiva") -> Ciudad Atractiva | F34: =IFERROR(__xludf.DUMMYFUNCTION("""COMPUTED_VALUE"""),"Festivales y Eventos") -> Festivales y Eventos | G34: =IFERROR(__xludf.DUMMYFUNCTION("""COMPUTED_VALUE"""),"Finalizada") -> Finalizada | H34: 31715868 | I34: 6079572 | J34: 33441 | K34: 103786 | L34: 81.182549 | M34: 305.58908 | N34: 231781 | O34: 227305 | P34: 76967 | Q34: 3329 | R34: 0 | S34: 0 | T34: 0 | U34: 0 | V34: 0 | W34: 0 | X34: 0 | Y34: 0 | Z34: 0 | AA34: 0 | AB34: 0 | AC34: 0 | AD34: https://www.facebook.com/reel/1401103571662551 | AE34: Pieza
A35: =IFERROR(__xludf.DUMMYFUNCTION("""COMPUTED_VALUE"""),"2434-DICFESGC") -> 2434-DICFESGC | B35: =IFERROR(__xludf.DUMMYFUNCTION("""COMPUTED_VALUE"""),"Verano en la Ciudad | Billboard Summer") -> Verano en la Ciudad | Billboard Summer | C35: =IFERROR(__xludf.DUMMYFUNCTION("""COMPUTED_VALUE"""),46031.0) -> 46031 | D35: =IFERROR(__xludf.DUMMYFUNCTION("""COMPUTED_VALUE"""),46039.0) -> 46039 | E35: =IFERROR(__xludf.DUMMYFUNCTION("""COMPUTED_VALUE"""),"Ciudad Atractiva") -> Ciudad Atractiva | F35: =IFERROR(__xludf.DUMMYFUNCTION("""COMPUTED_VALUE"""),"Festivales y Eventos") -> Festivales y Eventos | G35: =IFERROR(__xludf.DUMMYFUNCTION("""COMPUTED_VALUE"""),"Finalizada") -> Finalizada | H35: 12944042 | I35: 2874187 | J35: 12481 | K35: 29161 | L35: 137.44429 | M35: 443.88197 | N35: 175380 | O35: 172038 | P35: 58466 | Q35: 3201 | R35: 0 | S35: 0 | T35: 0 | U35: 0 | V35: 0 | W35: 0 | X35: 0 | Y35: 0 | Z35: 0 | AA35: 0 | AB35: 0 | AC35: 0 | AD35: https://www.facebook.com/reel/1385888349747054/ | AE35: Pieza
A36: =IFERROR(__xludf.DUMMYFUNCTION("""COMPUTED_VALUE"""),"2435-DICFESGC") -> 2435-DICFESGC | B36: =IFERROR(__xludf.DUMMYFUNCTION("""COMPUTED_VALUE"""),"Verano en la Ciudad | Atardeceres en los parques") -> Verano en la Ciudad | Atardeceres en los parques | C36: =IFERROR(__xludf.DUMMYFUNCTION("""COMPUTED_VALUE"""),46041.0) -> 46041 | D36: =IFERROR(__xludf.DUMMYFUNCTION("""COMPUTED_VALUE"""),46062.0) -> 46062 | E36: =IFERROR(__xludf.DUMMYFUNCTION("""COMPUTED_VALUE"""),"Ciudad Atractiva") -> Ciudad Atractiva | F36: =IFERROR(__xludf.DUMMYFUNCTION("""COMPUTED_VALUE"""),"Festivales y Eventos") -> Festivales y Eventos | G36: =IFERROR(__xludf.DUMMYFUNCTION("""COMPUTED_VALUE"""),"Finalizada") -> Finalizada | H36: 18780836 | I36: 4407686 | J36: 26564 | K36: 2036212 | L36: 2.9967616 | M36: 9.2234188 | N36: 107518 | O36: 86557 | P36: 31980 | Q36: 2402 | R36: 6925 | S36: 6908 | T36: 1374 | U36: 1022 | V36: 0 | W36: 0 | X36: 0 | Y36: 0 | Z36: 0 | AA36: 0 | AB36: 0 | AC36: 0 | AD36: https://www.facebook.com/GCBA/posts/pfbid0rLEuW4M93zccXsLKxEbAgdx71UvEEJJusTpaAfZzdSBaQDr7KZx36ckPuiwG1Rhql | AE36: Pieza
A37: =IFERROR(__xludf.DUMMYFUNCTION("""COMPUTED_VALUE"""),"2437-DICFESGC") -> 2437-DICFESGC | B37: =IFERROR(__xludf.DUMMYFUNCTION("""COMPUTED_VALUE"""),"Verano en la Ciudad | Verano en las plazas") -> Verano en la Ciudad | Verano en las plazas | C37: =IFERROR(__xludf.DUMMYFUNCTION("""COMPUTED_VALUE"""),46038.0) -> 46038 | D37: =IFERROR(__xludf.DUMMYFUNCTION("""COMPUTED_VALUE"""),46073.0) -> 46073 | E37: =IFERROR(__xludf.DUMMYFUNCTION("""COMPUTED_VALUE"""),"Ciudad Atractiva") -> Ciudad Atractiva | F37: =IFERROR(__xludf.DUMMYFUNCTION("""COMPUTED_VALUE"""),"Festivales y Eventos") -> Festivales y Eventos | G37: =IFERROR(__xludf.DUMMYFUNCTION("""COMPUTED_VALUE"""),"Finalizada") -> Finalizada | H37: 18930747 | I37: 5099312 | J37: 20844 | K37: 1292752 | L37: 5.5283542 | M37: 14.643758 | N37: 710718 | O37: 674580 | P37: 197102 | Q37: 16421 | R37: 0 | S37: 0 | T37: 0 | U37: 0 | V37: 0 | W37: 0 | X37: 0 | Y37: 0 | Z37: 0 | AA37: 0 | AB37: 0 | AC37: 0 | AD37: https://www.facebook.com/GCBA/posts/pfbid032UmvaRZ3eAJNRC4zHziYpyXVaPbbTucP4LKQNEh1BSxa3mTrzNz6mZGgDzRqYkTel | AE37: Pieza
A38: =IFERROR(__xludf.DUMMYFUNCTION("""COMPUTED_VALUE"""),"2439-DICINFGC") -> 2439-DICINFGC | B38: =IFERROR(__xludf.DUMMYFUNCTION("""COMPUTED_VALUE""")," Infraestructura I Bus Eléctricos: extensión recorrido") -> Infraestructura I Bus Eléctricos: extensión recorrido | C38: =IFERROR(__xludf.DUMMYFUNCTION("""COMPUTED_VALUE"""),46028.0) -> 46028 | D38: =IFERROR(__xludf.DUMMYFUNCTION("""COMPUTED_VALUE"""),46042.0) -> 46042 | E38: =IFERROR(__xludf.DUMMYFUNCTION("""COMPUTED_VALUE"""),"Movilidad") -> Movilidad | F38: =IFERROR(__xludf.DUMMYFUNCTION("""COMPUTED_VALUE"""),"Infraestructura") -> Infraestructura | G38: =IFERROR(__xludf.DUMMYFUNCTION("""COMPUTED_VALUE"""),"Finalizada") -> Finalizada | H38: 665162 | I38: 3616 | J38: 2743 | K38: 355350 | L38: 1.8718503 | M38: 1.8718503 | N38: 90056 | O38: 88895 | P38: 43812 | Q38: 2567 | R38: 0 | S38: 0 | T38: 0 | U38: 0 | V38: 0 | W38: 0 | X38: 0 | Y38: 0 | Z38: 0 | AA38: 0 | AB38: 0 | AC38: 0 | AD38: https://www.facebook.com/GCBA/posts/pfbid08jZno8hyH4wUURfHDj5eKgWYFcmdn1Lqh1sjbw1zmwZJ4dSZGEmpAeit2EdCjTLal | AE38: Pieza
A39: =IFERROR(__xludf.DUMMYFUNCTION("""COMPUTED_VALUE"""),"2441-DICINFGC") -> 2441-DICINFGC | B39: =IFERROR(__xludf.DUMMYFUNCTION("""COMPUTED_VALUE"""),"Infraestructura I Obras M2: Trambus ENERO") -> Infraestructura I Obras M2: Trambus ENERO | C39: =IFERROR(__xludf.DUMMYFUNCTION("""COMPUTED_VALUE"""),46035.0) -> 46035 | D39: =IFERROR(__xludf.DUMMYFUNCTION("""COMPUTED_VALUE"""),46053.0) -> 46053 | E39: =IFERROR(__xludf.DUMMYFUNCTION("""COMPUTED_VALUE"""),"Movilidad") -> Movilidad | F39: =IFERROR(__xludf.DUMMYFUNCTION("""COMPUTED_VALUE"""),"Infraestructura") -> Infraestructura | G39: =IFERROR(__xludf.DUMMYFUNCTION("""COMPUTED_VALUE"""),"Finalizada") -> Finalizada | H39: 3270390 | I39: 0 | J39: 47102 | K39: 469739 | L39: 2.0681974 | M39: 6.9621428 | N39: 56667 | O39: 55627 | P39: 19152 | Q39: 1989 | R39: 0 | S39: 0 | T39: 0 | U39: 0 | V39: 0 | W39: 0 | X39: 0 | Y39: 0 | Z39: 0 | AA39: 0 | AB39: 0 | AC39: 0 | AD39: https://www.facebook.com/GCBA/posts/pfbid0nA1q3xBcy1eJcYdmUe5hTkrG2zrbURY6VnDCqEubzKtTg6UhWBiGjhgYWJQUsK86l | AE39: Pieza
A40: =IFERROR(__xludf.DUMMYFUNCTION("""COMPUTED_VALUE"""),"2443-DICNEWAN") -> 2443-DICNEWAN | B40: =IFERROR(__xludf.DUMMYFUNCTION("""COMPUTED_VALUE"""),"Acciones de la Ciudad ante el calor extremo") -> Acciones de la Ciudad ante el calor extremo | C40: =IFERROR(__xludf.DUMMYFUNCTION("""COMPUTED_VALUE"""),46027.0) -> 46027 | D40: =IFERROR(__xludf.DUMMYFUNCTION("""COMPUTED_VALUE"""),46035.0) -> 46035 | E40: =IFERROR(__xludf.DUMMYFUNCTION("""COMPUTED_VALUE"""),"Cuidado") -> Cuidado | F40: =IFERROR(__xludf.DUMMYFUNCTION("""COMPUTED_VALUE"""),"Anuncios y Newsletter") -> Anuncios y Newsletter | G40: =IFERROR(__xludf.DUMMYFUNCTION("""COMPUTED_VALUE"""),"Finalizada") -> Finalizada | H40: 8154163 | I40: 0 | J40: 49108 | K40: 682062 | L40: 1.5975703 | M40: 11.955164 | N40: 236590 | O40: 233694 | P40: 54587 | Q40: 2742 | R40: 0 | S40: 0 | T40: 0 | U40: 0 | V40: 0 | W40: 0 | X40: 0 | Y40: 0 | Z40: 0 | AA40: 0 | AB40: 0 | AC40: 0 | AD40: https://www.facebook.com/GCBA/posts/pfbid0N5sbH3engzLHtbfZQM61dN6d9zBMxwsp4N1bpfX76sx6bnCZy4398mqDoXuTfdX5l
...

Sheet resumen_metricas
A1: id_cuentas | B1: nombre_campaña | C1: fecha_inicio | D1: fecha_fin | E1: eje | F1: area | G1: estado | H1: digital_impresiones | I1: digital_visualizaciones | J1: digital_clics | K1: meta_alcance | L1: meta_frecuencia | M1: frecuencia_total | N1: mails_enviados | O1: mails_entregados | P1: mails_aperturas | Q1: mails_clics | R1: call_enviado | S1: call_discado | T1: call_contactados | U1: call_efectivos | V1: ivr_audiencia | W1: ivr_realizados | X1: ivr_atendidos | Y1: ivr_escucha75 | Z1: ivr_marque1 | AA1: sms_enviados | AB1: sms_entregados | AC1: sms_clics | AD1: pieza_meta | AE1: pieza_mail
A2: 1871-AGOEDUGC | B2: Campaña GCBA | Educación | TUMO | C2: 45959 | D2: 46203 | E2: Cuidado | F2: Educación | G2: Finalizada | H2: 201273767 | I2: 21618564 | J2: 2637230 | K2: 9405671 | L2: 1.211467 | M2: 21.399193 | N2: 858783 | O2: 844304 | P2: 285060 | Q2: 8156 | R2: 4476 | S2: 4476 | T2: 1117 | U2: 854 | V2: 0 | W2: 0 | X2: 0 | Y2: 0 | Z2: 0 | AA2: 0 | AB2: 0 | AC2: 0 | AD2: https://www.facebook.com/reel/818777800864033
A3: 1895-SEPEPHGC | B3: PIEZAS M2 | MEPHU | REPAVIMENTACIÓN | C3: 46052 | D3: 46178 | E3: M2 | F3: Espacio Público e Higiene Urbana | G3: Finalizada | H3: 0 | I3: 0 | J3: 0 | K3: 0 | L3: 0 | M3: 0 | N3: 21556 | O3: 21228 | P3: 7666 | Q3: 393 | R3: 0 | S3: 0 | T3: 0 | U3: 0 | V3: 0 | W3: 0 | X3: 0 | Y3: 0 | Z3: 0 | AA3: 0 | AB3: 0 | AC3: 0 | AE3: Pieza
A4: 1896-SEPEPHGC | B4: PIEZAS M2 | MEPHU | LIMPIEZA INTENSIVA | C4: 46031 | D4: 46136 | E4: M2 | F4: Espacio Público e Higiene Urbana | G4: Finalizada | H4: 0 | I4: 0 | J4: 0 | K4: 0 | L4: 0 | M4: 0 | N4: 648150 | O4: 634433 | P4: 181275 | Q4: 1540 | R4: 0 | S4: 0 | T4: 0 | U4: 0 | V4: 0 | W4: 0 | X4: 0 | Y4: 0 | Z4: 0 | AA4: 0 | AB4: 0 | AC4: 0 | AE4: Pieza
A5: 1933-SEPINFGC | B5: CAMPAÑA GCBA | INFRAESTRUCTURA | Campaña 360° Movilidad 2025 | C5: 45936 | D5: 46081 | E5: Movilidad | F5: Infraestructura | G5: Finalizada | H5: 120265231 | I5: 14353067 | J5: 530499 | K5: 6681997 | L5: 0.9273355 | M5: 17.998396 | N5: 2962736 | O5: 3124082 | P5: 1008617 | Q5: 19835 | R5: 0 | S5: 0 | T5: 0 | U5: 0 | V5: 0 | W5: 0 | X5: 0 | Y5: 0 | Z5: 0 | AA5: 16505 | AB5: 15794 | AC5: 82 | AD5: https://www.facebook.com/GCBA/posts/pfbid02ySETv8mbLPx3NFrrHh1eRhVRmMimid99iTcJQu2RtwUS7KCAiwKP9qoSStF1cMSml | AE5: Pieza
A6: 1942-SEPEPHGC | B6: DGPLES | MEPHU | REPARACIÓN DE VEREDAS | C6: 46031 | D6: 46223 | E6: M2 | F6: Espacio Público e Higiene Urbana | G6: Finalizada | H6: 0 | I6: 0 | J6: 0 | K6: 0 | L6: 0 | M6: 0 | N6: 69878 | O6: 68815 | P6: 23523 | Q6: 1379 | R6: 0 | S6: 0 | T6: 0 | U6: 0 | V6: 0 | W6: 0 | X6: 0 | Y6: 0 | Z6: 0 | AA6: 0 | AB6: 0 | AC6: 0 | AE6: Pieza
A7: 1943-SEPEPHGC | B7: DGPLES | MEPHU | READOQUINADO | C7: 46031 | D7: 46223 | E7: M2 | F7: Espacio Público e Higiene Urbana | G7: Finalizada | H7: 0 | I7: 0 | J7: 0 | K7: 0 | L7: 0 | M7: 0 | N7: 15590 | O7: 15371 | P7: 5329 | Q7: 415 | R7: 0 | S7: 0 | T7: 0 | U7: 0 | V7: 0 | W7: 0 | X7: 0 | Y7: 0 | Z7: 0 | AA7: 0 | AB7: 0 | AC7: 0 | AE7: Pieza
A8: 1946-SEPEPHGC | B8: CAMPAÑA GCBA | MEPHU | PLUVIALES | C8: 46038 | D8: 46223 | E8: M2 | F8: Espacio Público e Higiene Urbana | G8: Finalizada | H8: 0 | I8: 0 | J8: 0 | K8: 0 | L8: 0 | M8: 0 | N8: 18528 | O8: 18309 | P8: 6404 | Q8: 426 | R8: 0 | S8: 0 | T8: 0 | U8: 0 | V8: 0 | W8: 0 | X8: 0 | Y8: 0 | Z8: 0 | AA8: 0 | AB8: 0 | AC8: 0 | AE8: Pieza
A9: 1964-SEPEPHGC | B9: MEPHU RECAMBIO TECNOLÓGICO M2 | C9: 46071 | D9: 46220 | E9: M2 | F9: Espacio Público e Higiene Urbana | G9: Finalizada | H9: 0 | I9: 0 | J9: 0 | K9: 0 | L9: 0 | M9: 0 | N9: 444872 | O9: 439325 | P9: 133653 | Q9: 3043 | R9: 0 | S9: 0 | T9: 0 | U9: 0 | V9: 0 | W9: 0 | X9: 0 | Y9: 0 | Z9: 0 | AA9: 0 | AB9: 0 | AC9: 0 | AE9: Pieza
A10: 2033-SEPEPHGC | B10: M2 PODA | C10: 46035 | D10: 46216 | E10: M2 | F10: Espacio Público e Higiene Urbana | G10: Finalizada | H10: 0 | I10: 0 | J10: 0 | K10: 0 | L10: 0 | M10: 0 | N10: 145204 | O10: 141927 | P10: 46936 | Q10: 2044 | R10: 0 | S10: 0 | T10: 0 | U10: 0 | V10: 0 | W10: 0 | X10: 0 | Y10: 0 | Z10: 0 | AA10: 0 | AB10: 0 | AC10: 0 | AE10: Pieza
A11: 2100-OCTSALGC | B11: Cesac 12 - Más consultorios | C11: 46013 | D11: 46027 | E11: Cuidado | F11: Salud | G11: Finalizada | H11: 5541119 | I11: 634751 | J11: 14536 | K11: 0 | L11: 0 | M11: 0 | N11: 81077 | O11: 79591 | P11: 31217 | Q11: 1060 | R11: 0 | S11: 0 | T11: 0 | U11: 0 | V11: 0 | W11: 0 | X11: 0 | Y11: 0 | Z11: 0 | AA11: 0 | AB11: 0 | AC11: 0
A12: 2108-OCTEDUGC | B12: Inscripción 2025 a Profesorados de la Ciudad | C12: 45952 | D12: 46073 | E12: Cuidado | F12: Educación | G12: Finalizada | H12: 24528982 | I12: 0 | J12: 555619 | K12: 1745904 | L12: 1.3171446 | M12: 14.049445 | N12: 132413 | O12: 130535 | P12: 87400 | Q12: 8263 | R12: 0 | S12: 0 | T12: 0 | U12: 0 | V12: 0 | W12: 0 | X12: 0 | Y12: 0 | Z12: 0 | AA12: 0 | AB12: 0 | AC12: 0 | AD12: https://www.facebook.com/GCBA/posts/1295953569230956
A13: 2109-OCTEPHGC | B13: LIMPIEZA DE FACHADAS | M2 | C13: 46028 | D13: 46099 | E13: M2 | F13: Espacio Público e Higiene Urbana | G13: Finalizada | H13: 0 | I13: 0 | J13: 0 | K13: 0 | L13: 0 | M13: 0 | N13: 923 | O13: 898 | P13: 294 | Q13: 38 | R13: 0 | S13: 0 | T13: 0 | U13: 0 | V13: 0 | W13: 0 | X13: 0 | Y13: 0 | Z13: 0 | AA13: 0 | AB13: 0 | AC13: 0 | AE13: Pieza
A14: 2130-OCTSALGC | B14: Hospital Pirovano: Remodelaciones | C14: 46050 | D14: 46066 | E14: Cuidado | F14: Salud | G14: Finalizada | H14: 3945078 | I14: 0 | J14: 9197 | K14: 1208470 | L14: 1.0665105 | M14: 3.2645229 | N14: 100614 | O14: 99157 | P14: 42370 | Q14: 787 | R14: 0 | S14: 0 | T14: 0 | U14: 0 | V14: 0 | W14: 0 | X14: 0 | Y14: 0 | Z14: 0 | AA14: 0 | AB14: 0 | AC14: 0 | AE14: Pieza
A15: 2145-OCTVINGC | B15: PIEZAS M2 | VINCULO CIUDADANO (GESTIÓN COMUNAL) | OBRAS EN PARQUES Y PLAZAS (PATIOS DE JUEGOS) Plan 2025 | C15: 46020 | D15: 46174 | E15: M2 | F15: Vínculo Ciudadano | G15: Finalizada | H15: 2352745 | I15: 0 | J15: 7138 | K15: 1084144 | L15: 1.9502769 | M15: 2.1701407 | N15: 1136573 | O15: 1111059 | P15: 368628 | Q15: 9109 | R15: 0 | S15: 0 | T15: 0 | U15: 0 | V15: 0 | W15: 0 | X15: 0 | Y15: 0 | Z15: 0 | AA15: 0 | AB15: 0 | AC15: 0 | AD15: https://www.facebook.com/GCBA/posts/pfbid02j9NjjKC7QJSSUrKxkX55nDiWFRmCpVKSS3w7J3VpQA3DakuvLQQ5B3z96orCNRMUl | AE15: Pieza
A16: 2183-OCTSALGC | B16: Sistema de Salud Público - Genérico | C16: 45992 | D16: 46068 | E16: Cuidado | F16: Salud | G16: Finalizada | H16: 63685126 | I16: 11819633 | J16: 218716 | K16: 2510514 | L16: 2.9775759 | M16: 25.367365 | N16: 0 | O16: 0 | P16: 0 | Q16: 0 | R16: 0 | S16: 0 | T16: 0 | U16: 0 | V16: 0 | W16: 0 | X16: 0 | Y16: 0 | Z16: 0 | AA16: 44842 | AB16: 43029 | AC16: 724 | AD16: https://www.facebook.com/GCBA/posts/pfbid02QwxLwyKnw9PCTX9BXhgSSH5hJ3u56noy7igZq9orxmSsVPqjj4MMUZ5SD9xXWWQ3l
A17: 2227-NOVINFGC | B17: Infraestructura - SBASE | Campaña GCBA | Seguridad en Subte | C17: 45981 | D17: 46037 | E17: Movilidad | F17: Infraestructura | G17: Finalizada | H17: 56510666 | I17: 13306488 | J17: 109062 | K17: 2996348 | L17: 1.9993095 | M17: 18.859847 | N17: 448806 | O17: 441370 | P17: 157871 | Q17: 1073 | R17: 0 | S17: 0 | T17: 0 | U17: 0 | V17: 0 | W17: 0 | X17: 0 | Y17: 0 | Z17: 0 | AA17: 0 | AB17: 0 | AC17: 0 | AD17: https://www.facebook.com/GCBA/posts/pfbid0swuyoC42Lys1AAsD6UQ7EPU5B43KXVdVXxxXU4X9oHEJ7DjKXtavLAdDHd6BpccBl | AE17: Pieza
A18: 2239-NOVSALGC | B18: Cuidados del Calor 2025 - Prevención | C18: 45996 | D18: 46081 | E18: Cuidado | F18: Salud | G18: Finalizada | H18: 44318251 | I18: 7628858 | J18: 207888 | K18: 3270088 | L18: 3.1020116 | M18: 13.552617 | N18: 393084 | O18: 386497 | P18: 128673 | Q18: 1026 | R18: 0 | S18: 0 | T18: 0 | U18: 0 | V18: 60114 | W18: 60114 | X18: 50294 | Y18: 14803 | Z18: 0 | AA18: 44261 | AB18: 42094 | AC18: 432 | AD18: https://www.facebook.com/GCBA/posts/pfbid02fZ6eoJSg8zqDVE3RogP3nnn5hqo9sxTPxRzzs7HgyWNUmM6XZmtSLLNohgBDJZ2xl | AE18: Pieza
A19: 2240-NOVSALGC | B19: Cuidados del Calor 2025 - Síntomas | C19: 46009 | D19: 46081 | E19: Cuidado | F19: Salud | G19: Finalizada | H19: 37792450 | I19: 5153493 | J19: 136800 | K19: 1979868 | L19: 3.4276906 | M19: 19.088369 | N19: 202759 | O19: 198265 | P19: 46872 | Q19: 167 | R19: 0 | S19: 0 | T19: 0 | U19: 0 | V19: 0 | W19: 0 | X19: 0 | Y19: 0 | Z19: 0 | AA19: 0 | AB19: 0 | AC19: 0 | AD19: https://www.facebook.com/GCBA/posts/pfbid02XEqLAZ3ja1iUkCQ1AFBkuUXwxFv9zsX5K86BwUhreM4wjGsmh9yx8x8cEFwBnwo1l | AE19: Pieza
A20: 2241-NOVSALGC | B20: Cuidados del Calor 2025 - Alertas Meteorológicas | C20: 46020 | D20: 46058 | E20: Cuidado | F20: Salud | G20: Finalizada | H20: 6328947 | I20: 0 | J20: 50769 | K20: 2394484 | L20: 1.3164298 | M20: 2.6431361 | N20: 246623 | O20: 243978 | P20: 116854 | Q20: 114 | R20: 0 | S20: 0 | T20: 0 | U20: 0 | V20: 0 | W20: 0 | X20: 0 | Y20: 0 | Z20: 0 | AA20: 62485 | AB20: 59237 | AC20: 372 | AD20: https://www.facebook.com/GCBA/posts/pfbid02j9NjjKC7QJSSUrKxkX55nDiWFRmCpVKSS3w7J3VpQA3DakuvLQQ5B3z96orCNRMUl
A21: 2255-NOVSALGC | B21: Sistema de Salud Público - Geolocalizado | C21: 46008 | D21: 46068 | E21: Cuidado | F21: Salud | G21: Finalizada | H21: 38197009 | I21: 0 | J21: 552532 | K21: 1566896 | L21: 3.6226406 | M21: 24.377501 | N21: 907590 | O21: 862876 | P21: 284653 | Q21: 624 | R21: 0 | S21: 0 | T21: 0 | U21: 0 | V21: 0 | W21: 0 | X21: 0 | Y21: 0 | Z21: 0 | AA21: 0 | AB21: 0 | AC21: 0 | AD21: https://www.facebook.com/GCBA/posts/pfbid02dx5PKW9dhfnoR52qjj3Cxnq9opfoRmH6HwTJx9uacynmmZet5vn1FL6Xavv3J8ZXl | AE21: Pieza
A22: 2256-NOVSALGC | B22: Sistema de Salud Público - Diferenciado x Audiencias | C22: 46010 | D22: 46068 | E22: Cuidado | F22: Salud | G22: Finalizada | H22: 28261480 | I22: 5404995 | J22: 94248 | K22: 1318610 | L22: 2.6421224 | M22: 21.432781 | N22: 348034 | O22: 344435 | P22: 178103 | Q22: 356 | R22: 0 | S22: 0 | T22: 0 | U22: 0 | V22: 0 | W22: 0 | X22: 0 | Y22: 0 | Z22: 0 | AA22: 0 | AB22: 0 | AC22: 0 | AD22: https://www.facebook.com/GCBA/posts/pfbid02SB5PG237gJvSQGMPLHpQAP5b6uxqxh8AqRUS3csVWmCnYyvd77i8d67LSBMnBtg8l | AE22: Pieza
A23: 2293-NOVFESGC | B23: LA CIUDAD MAS LINDA DEL MUNDO | C23: 45994 | D23: 46053 | E23: Ciudad Atractiva | F23: Festivales y Eventos | G23: Finalizada | H23: 75245249 | I23: 13466546 | J23: 799082 | K23: 7843297 | L23: 1.9541976 | M23: 9.5935739 | N23: 657996 | O23: 645327 | P23: 198939 | Q23: 10076 | R23: 0 | S23: 0 | T23: 0 | U23: 0 | V23: 0 | W23: 0 | X23: 0 | Y23: 0 | Z23: 0 | AA23: 0 | AB23: 0 | AC23: 0 | AD23: https://www.facebook.com/GCBA/posts/pfbid0yZFqpziwsSvEpGHnbKnvgTkMNo6Ys8gfLmUBqRKhRCH71tiHcf1cXzt2RhCmokjMl
A24: 2318-ENEINFGC | B24: Infraestructura I Cambio de sentido Avelino Díaz y Las Casas | C24: 46040 | D24: 46053 | E24: M2 | F24: Infraestructura | G24: Finalizada | H24: 656152 | I24: 0 | J24: 4677 | K24: 293307 | L24: 2.2370826 | M24: 2.2370826 | N24: 34125 | O24: 33543 | P24: 11623 | Q24: 221 | R24: 0 | S24: 0 | T24: 0 | U24: 0 | V24: 0 | W24: 0 | X24: 0 | Y24: 0 | Z24: 0 | AA24: 0 | AB24: 0 | AC24: 0 | AD24: https://www.facebook.com/GCBA/posts/pfbid02fhrsXdCgnCn19Gs1k1PTjbTdAfYLBMqW3w4zhQLgJqH8r8uW4azYikpQk6Js8WNcl | AE24: Pieza
A25: 2322-NOVEDUGC | B25: TUMO Parque de la Innovación | C25: 46006 | D25: 46265 | E25: Cuidado | F25: Educación | G25: Activa | H25: 37630874 | I25: 2298580 | J25: 197893 | K25: 845956 | L25: 2.7451924 | M25: 44.483252 | N25: 390326 | O25: 382880 | P25: 132608 | Q25: 2847 | R25: 2471 | S25: 2471 | T25: 938 | U25: 695 | V25: 0 | W25: 0 | X25: 0 | Y25: 0 | Z25: 0 | AA25: 0 | AB25: 0 | AC25: 0 | AD25: https://www.facebook.com/reel/1259490412867632 | AE25: Pieza
A26: 2407-DICDHHGC | B26: Red de atención - Comuna 14 | C26: 46009 | D26: 46035 | E26: Cuidado | F26: Desarrollo Humano y Hábitat | G26: Finalizada | H26: 5648733 | I26: 908168 | J26: 31911 | K26: 345688 | L26: 1.5532706 | M26: 16.340553 | N26: 82291 | O26: 80644 | P26: 34390 | Q26: 427 | R26: 41000 | S26: 38657 | T26: 7137 | U26: 4305 | V26: 0 | W26: 0 | X26: 0 | Y26: 0 | Z26: 0 | AA26: 0 | AB26: 0 | AC26: 0 | AD26: https://www.facebook.com/GCBA/posts/pfbid034rFdFhu5CMuLHbUxCF393aMxjQ6Uzsq6seyeRjcjNKtzSymPzkApKt81BUxEeVj3l | AE26: Pieza
A27: 2410-DICJDGAG | B27: RDV JM | Villa Devoto 15/12 | C27: 46013 | D27: 46024 | E27: Cercanía | F27: Jefatura de Gobierno | G27: Finalizada | H27: 14229634 | I27: 322142 | J27: 29184 | K27: 0 | L27: 0 | M27: 0 | N27: 30540 | O27: 30402 | P27: 9314 | Q27: 336 | R27: 0 | S27: 0 | T27: 0 | U27: 0 | V27: 20067.047 | W27: 20067.047 | X27: 18323.305 | Y27: 7084.077 | Z27: 180 | AA27: 0 | AB27: 0 | AC27: 0
A28: 2412-DICJDGAG | B28: RDV JM | Colegiales 19/12 | C28: 46014 | D28: 46025 | E28: Cercanía | F28: Jefatura de Gobierno | G28: Finalizada | H28: 1782381 | I28: 139137 | J28: 7011 | K28: 0 | L28: 0 | M28: 0 | N28: 24878 | O28: 24515 | P28: 6879 | Q28: 163 | R28: 6770 | S28: 6769 | T28: 1751 | U28: 1295 | V28: 26545.519 | W28: 26545.519 | X28: 23902.879 | Y28: 10339.329 | Z28: 126 | AA28: 0 | AB28: 0 | AC28: 0
A29: 2423-DICJDGGC | B29: Festejos Responsables 2025 | C29: 46014 | D29: 46023 | E29: Cuidado | F29: Jefatura de Gobierno | G29: Finalizada | H29: 113032 | I29: 0 | J29: 5003 | K29: 0 | L29: 0 | M29: 0 | N29: 497431 | O29: 490986 | P29: 208233 | Q29: 1469 | R29: 12000 | S29: 11037 | T29: 2752 | U29: 2052 | V29: 0 | W29: 0 | X29: 0 | Y29: 0 | Z29: 0 | AA29: 0 | AB29: 0 | AC29: 0
A30: 2424-DICFESGC | B30: Verano en Buenos Aires 2026 | Generico | C30: 46029 | D30: 46081 | E30: Ciudad Atractiva | F30: Festivales y Eventos | G30: Finalizada | H30: 32919907 | I30: 2721109 | J30: 164357 | K30: 3975434 | L30: 2.6766625 | M30: 8.2808335 | N30: 306526 | O30: 303199 | P30: 151566 | Q30: 7233 | R30: 0 | S30: 0 | T30: 0 | U30: 0 | V30: 0 | W30: 0 | X30: 0 | Y30: 0 | Z30: 0 | AA30: 0 | AB30: 0 | AC30: 0 | AD30: https://www.facebook.com/GCBA/posts/pfbid02PmAtvdzD176mjzPpPRZmFQTNXzNjqoKr7o9wByEVUtzkzYpigMPqtXRGysNDa6Wjl | AE30: Pieza
A31: 2425-DICEPHGC | B31: Parques Iluminados M2 | C31: 46163 | D31: 46190 | E31: M2 | F31: Espacio Público e Higiene Urbana | G31: Finalizada | H31: 0 | I31: 0 | J31: 0 | K31: 0 | L31: 0 | M31: 0 | N31: 21456 | O31: 21233 | P31: 7139 | Q31: 191 | R31: 0 | S31: 0 | T31: 0 | U31: 0 | V31: 0 | W31: 0 | X31: 0 | Y31: 0 | Z31: 0 | AA31: 0 | AB31: 0 | AC31: 0 | AE31: Pieza
A32: 2426-DICSALGC | B32: Deploy HIS Ambulatorio | C32: 46030 | D32: 46030 | E32: Cuidado | F32: Salud | G32: Finalizada | H32: 0 | I32: 0 | J32: 0 | K32: 0 | L32: 0 | M32: 0 | N32: 3471 | O32: 3443 | P32: 1477 | Q32: 169 | R32: 0 | S32: 0 | T32: 0 | U32: 0 | V32: 0 | W32: 0 | X32: 0 | Y32: 0 | Z32: 0 | AA32: 0 | AB32: 0 | AC32: 0 | AE32: Pieza
A33: 2430-DICPCCVC | B33: DGPCyC | Verano 2026 - Misión Bomberos: Un día en la estación | C33: 46029 | D33: 46029 | E33: Cercanía | F33: Cercanía y PC | G33: Finalizada | H33: 0 | I33: 0 | J33: 0 | K33: 0 | L33: 0 | M33: 0 | N33: 26990 | O33: 26313 | P33: 4518 | Q33: 419 | R33: 0 | S33: 0 | T33: 0 | U33: 0 | V33: 0 | W33: 0 | X33: 0 | Y33: 0 | Z33: 0 | AA33: 0 | AB33: 0 | AC33: 0 | AE33: Pieza
A34: 2433-DICFESGC | B34: Verano en la Ciudad | AftersBA | C34: 46035 | D34: 46071 | E34: Ciudad Atractiva | F34: Festivales y Eventos | G34: Finalizada | H34: 31715868 | I34: 6079572 | J34: 33441 | K34: 103786 | L34: 81.182549 | M34: 305.58908 | N34: 231781 | O34: 227305 | P34: 76967 | Q34: 3329 | R34: 0 | S34: 0 | T34: 0 | U34: 0 | V34: 0 | W34: 0 | X34: 0 | Y34: 0 | Z34: 0 | AA34: 0 | AB34: 0 | AC34: 0 | AD34: https://www.facebook.com/reel/1401103571662551 | AE34: Pieza
A35: 2434-DICFESGC | B35: Verano en la Ciudad | Billboard Summer | C35: 46031 | D35: 46039 | E35: Ciudad Atractiva | F35: Festivales y Eventos | G35: Finalizada | H35: 12944042 | I35: 2874187 | J35: 12481 | K35: 29161 | L35: 137.44429 | M35: 443.88197 | N35: 175380 | O35: 172038 | P35: 58466 | Q35: 3201 | R35: 0 | S35: 0 | T35: 0 | U35: 0 | V35: 0 | W35: 0 | X35: 0 | Y35: 0 | Z35: 0 | AA35: 0 | AB35: 0 | AC35: 0 | AD35: https://www.facebook.com/reel/1385888349747054/ | AE35: Pieza
A36: 2435-DICFESGC | B36: Verano en la Ciudad | Atardeceres en los parques | C36: 46041 | D36: 46062 | E36: Ciudad Atractiva | F36: Festivales y Eventos | G36: Finalizada | H36: 18780836 | I36: 4407686 | J36: 26564 | K36: 2036212 | L36: 2.9967616 | M36: 9.2234188 | N36: 107518 | O36: 86557 | P36: 31980 | Q36: 2402 | R36: 6925 | S36: 6908 | T36: 1374 | U36: 1022 | V36: 0 | W36: 0 | X36: 0 | Y36: 0 | Z36: 0 | AA36: 0 | AB36: 0 | AC36: 0 | AD36: https://www.facebook.com/GCBA/posts/pfbid0rLEuW4M93zccXsLKxEbAgdx71UvEEJJusTpaAfZzdSBaQDr7KZx36ckPuiwG1Rhql | AE36: Pieza
A37: 2437-DICFESGC | B37: Verano en la Ciudad | Verano en las plazas | C37: 46038 | D37: 46073 | E37: Ciudad Atractiva | F37: Festivales y Eventos | G37: Finalizada | H37: 18930747 | I37: 5099312 | J37: 20844 | K37: 1292752 | L37: 5.5283542 | M37: 14.643758 | N37: 710718 | O37: 674580 | P37: 197102 | Q37: 16421 | R37: 0 | S37: 0 | T37: 0 | U37: 0 | V37: 0 | W37: 0 | X37: 0 | Y37: 0 | Z37: 0 | AA37: 0 | AB37: 0 | AC37: 0 | AD37: https://www.facebook.com/GCBA/posts/pfbid032UmvaRZ3eAJNRC4zHziYpyXVaPbbTucP4LKQNEh1BSxa3mTrzNz6mZGgDzRqYkTel | AE37: Pieza
A38: 2439-DICINFGC | B38: Infraestructura I Bus Eléctricos: extensión recorrido | C38: 46028 | D38: 46042 | E38: Movilidad | F38: Infraestructura | G38: Finalizada | H38: 665162 | I38: 3616 | J38: 2743 | K38: 355350 | L38: 1.8718503 | M38: 1.8718503 | N38: 90056 | O38: 88895 | P38: 43812 | Q38: 2567 | R38: 0 | S38: 0 | T38: 0 | U38: 0 | V38: 0 | W38: 0 | X38: 0 | Y38: 0 | Z38: 0 | AA38: 0 | AB38: 0 | AC38: 0 | AD38: https://www.facebook.com/GCBA/posts/pfbid08jZno8hyH4wUURfHDj5eKgWYFcmdn1Lqh1sjbw1zmwZJ4dSZGEmpAeit2EdCjTLal | AE38: Pieza
A39: 2441-DICINFGC | B39: Infraestructura I Obras M2: Trambus ENERO | C39: 46035 | D39: 46053 | E39: Movilidad | F39: Infraestructura | G39: Finalizada | H39: 3270390 | I39: 0 | J39: 47102 | K39: 469739 | L39: 2.0681974 | M39: 6.9621428 | N39: 56667 | O39: 55627 | P39: 19152 | Q39: 1989 | R39: 0 | S39: 0 | T39: 0 | U39: 0 | V39: 0 | W39: 0 | X39: 0 | Y39: 0 | Z39: 0 | AA39: 0 | AB39: 0 | AC39: 0 | AD39: https://www.facebook.com/GCBA/posts/pfbid0nA1q3xBcy1eJcYdmUe5hTkrG2zrbURY6VnDCqEubzKtTg6UhWBiGjhgYWJQUsK86l | AE39: Pieza
A40: 2443-DICNEWAN | B40: Acciones de la Ciudad ante el calor extremo | C40: 46027 | D40: 46035 | E40: Cuidado | F40: Anuncios y Newsletter | G40: Finalizada | H40: 8154163 | I40: 0 | J40: 49108 | K40: 682062 | L40: 1.5975703 | M40: 11.955164 | N40: 236590 | O40: 233694 | P40: 54587 | Q40: 2742 | R40: 0 | S40: 0 | T40: 0 | U40: 0 | V40: 0 | W40: 0 | X40: 0 | Y40: 0 | Z40: 0 | AA40: 0 | AB40: 0 | AC40: 0 | AD40: https://www.facebook.com/GCBA/posts/pfbid0N5sbH3engzLHtbfZQM61dN6d9zBMxwsp4N1bpfX76sx6bnCZy4398mqDoXuTfdX5l
...

Sheet Cuentas
A1: id_cuentas | B1: nombre_campaña | C1: fecha_inicio | D1: fecha_fin | E1: eje | F1: area | G1: estado | H1: estado_cuentas
A2: 1871-AGOEDUGC | B2: Campaña GCBA | Educación | TUMO | C2: 45959 | D2: 46203 | E2: Cuidado | F2: Educación | G2: Finalizada | H2: Activa
A3: 1895-SEPEPHGC | B3: PIEZAS M2 | MEPHU | REPAVIMENTACIÓN | C3: 46052 | D3: 46178 | E3: M2 | F3: Espacio Público e Higiene Urbana | G3: Finalizada | H3: Finalizada
A4: 1896-SEPEPHGC | B4: PIEZAS M2 | MEPHU | LIMPIEZA INTENSIVA | C4: 46031 | D4: 46136 | E4: M2 | F4: Espacio Público e Higiene Urbana | G4: Finalizada | H4: Pausada
A5: 1933-SEPINFGC | B5: CAMPAÑA GCBA | INFRAESTRUCTURA | Campaña 360° Movilidad 2025 | C5: 45936 | D5: 46081 | E5: Movilidad | F5: Infraestructura | G5: Finalizada | H5: Finalizada
